An error occurred while executing the following cell:
------------------
%cd /content/GANJax

import os

try:
    import cv2
except ModuleNotFoundError:
    %pip install -qq opencv-python
    import cv2
import matplotlib.pyplot as plt

from jax import numpy as jnp, random

try:
    from gan.progan import ProGAN as GAN
except ModuleNotFoundError:
    %pip install -qq gan
    from gan.progan import ProGAN as GAN
try:
    from utils.save_and_load import save_gan
except ModuleNotFoundError:
    %pip install -qq utils
    from utils.save_and_load import save_gan

try:
    import tensorflow as tf
except ModuleNotFoundError:
    %pip install -qq tensorflow
    import tensorflow as tf
from gan.dcgan import DCGAN as GAN
from utils.data import load_images_celeba_64

print(tf.__version__)
print("DEVICES VISIBLE BY TF - ", tf.config.list_physical_devices())
------------------

---------------------------------------------------------------------------
TypeError                                 Traceback (most recent call last)
/tmp/ipykernel_6903/503770219.py in <module>
     13 
     14 try:
---> 15     from gan.progan import ProGAN as GAN
     16 except ModuleNotFoundError:
     17     get_ipython().run_line_magic('pip', 'install -qq gan')

/content/GANJax/gan/progan/__init__.py in <module>
----> 1 from gan.progan.ProGAN import ProGAN
      2 

/content/GANJax/gan/progan/ProGAN.py in <module>
      1 from gan.progan.modules import ProGenerator, ProDiscriminator
      2 from gan.progan.config import ProGANConfig
----> 3 from gan.progan.trainer import ProGANTrainer
      4 
      5 class ProGAN(object):

/content/GANJax/gan/progan/trainer.py in <module>
      6 import matplotlib.pyplot as plt
      7 import optax
----> 8 import tensorflow as tf
      9 
     10 from gan.progan.modules import ProGenerator, ProDiscriminator

~/miniconda3/envs/py37/lib/python3.7/site-packages/tensorflow/__init__.py in <module>
     35 import typing as _typing
     36 
---> 37 from tensorflow.python.tools import module_util as _module_util
     38 from tensorflow.python.util.lazy_loader import LazyLoader as _LazyLoader
     39 

~/miniconda3/envs/py37/lib/python3.7/site-packages/tensorflow/python/__init__.py in <module>
     35 
     36 from tensorflow.python import pywrap_tensorflow as _pywrap_tensorflow
---> 37 from tensorflow.python.eager import context
     38 
     39 # pylint: enable=wildcard-import

~/miniconda3/envs/py37/lib/python3.7/site-packages/tensorflow/python/eager/context.py in <module>
     27 import six
     28 
---> 29 from tensorflow.core.framework import function_pb2
     30 from tensorflow.core.protobuf import config_pb2
     31 from tensorflow.core.protobuf import coordination_config_pb2

~/miniconda3/envs/py37/lib/python3.7/site-packages/tensorflow/core/framework/function_pb2.py in <module>
     14 
     15 
---> 16 from tensorflow.core.framework import attr_value_pb2 as tensorflow_dot_core_dot_framework_dot_attr__value__pb2
     17 from tensorflow.core.framework import node_def_pb2 as tensorflow_dot_core_dot_framework_dot_node__def__pb2
     18 from tensorflow.core.framework import op_def_pb2 as tensorflow_dot_core_dot_framework_dot_op__def__pb2

~/miniconda3/envs/py37/lib/python3.7/site-packages/tensorflow/core/framework/attr_value_pb2.py in <module>
     14 
     15 
---> 16 from tensorflow.core.framework import tensor_pb2 as tensorflow_dot_core_dot_framework_dot_tensor__pb2
     17 from tensorflow.core.framework import tensor_shape_pb2 as tensorflow_dot_core_dot_framework_dot_tensor__shape__pb2
     18 from tensorflow.core.framework import types_pb2 as tensorflow_dot_core_dot_framework_dot_types__pb2

~/miniconda3/envs/py37/lib/python3.7/site-packages/tensorflow/core/framework/tensor_pb2.py in <module>
     14 
     15 
---> 16 from tensorflow.core.framework import resource_handle_pb2 as tensorflow_dot_core_dot_framework_dot_resource__handle__pb2
     17 from tensorflow.core.framework import tensor_shape_pb2 as tensorflow_dot_core_dot_framework_dot_tensor__shape__pb2
     18 from tensorflow.core.framework import types_pb2 as tensorflow_dot_core_dot_framework_dot_types__pb2

~/miniconda3/envs/py37/lib/python3.7/site-packages/tensorflow/core/framework/resource_handle_pb2.py in <module>
     14 
     15 
---> 16 from tensorflow.core.framework import tensor_shape_pb2 as tensorflow_dot_core_dot_framework_dot_tensor__shape__pb2
     17 from tensorflow.core.framework import types_pb2 as tensorflow_dot_core_dot_framework_dot_types__pb2
     18 

~/miniconda3/envs/py37/lib/python3.7/site-packages/tensorflow/core/framework/tensor_shape_pb2.py in <module>
     40       message_type=None, enum_type=None, containing_type=None,
     41       is_extension=False, extension_scope=None,
---> 42       serialized_options=None, file=DESCRIPTOR),
     43     _descriptor.FieldDescriptor(
     44       name='name', full_name='tensorflow.TensorShapeProto.Dim.name', index=1,

~/miniconda3/envs/py37/lib/python3.7/site-packages/google/protobuf/descriptor.py in __new__(cls, name, full_name, index, number, type, cpp_type, label, default_value, message_type, enum_type, containing_type, is_extension, extension_scope, options, serialized_options, has_default_value, containing_oneof, json_name, file, create_key)
    558                 has_default_value=True, containing_oneof=None, json_name=None,
    559                 file=None, create_key=None):  # pylint: disable=redefined-builtin
--> 560       _message.Message._CheckCalledFromGeneratedFile()
    561       if is_extension:
    562         return _message.default_pool.FindExtensionByName(full_name)

TypeError: Descriptors cannot not be created directly.
If this call came from a _pb2.py file, your generated code is out of date and must be regenerated with protoc >= 3.19.0.
If you cannot immediately regenerate your protos, some other possible workarounds are:
 1. Downgrade the protobuf package to 3.20.x or lower.
 2. Set PROTOCOL_BUFFERS_PYTHON_IMPLEMENTATION=python (but this will use pure-Python parsing and will be much slower).

More information: https://developers.google.com/protocol-buffers/docs/news/2022-05-06#python-updates
TypeError: Descriptors cannot not be created directly.
If this call came from a _pb2.py file, your generated code is out of date and must be regenerated with protoc >= 3.19.0.
If you cannot immediately regenerate your protos, some other possible workarounds are:
 1. Downgrade the protobuf package to 3.20.x or lower.
 2. Set PROTOCOL_BUFFERS_PYTHON_IMPLEMENTATION=python (but this will use pure-Python parsing and will be much slower).

More information: https://developers.google.com/protocol-buffers/docs/news/2022-05-06#python-updates
